(base) root@askar-VirtualBox:/mnt/share_ubuntu/registr_page# python3.11 manage.py runserver
Watching for file changes with StatReloader
Performing system checks...

Exception in thread django-main-thread:
Traceback (most recent call last):
  File "/root/anaconda3/lib/python3.11/threading.py", line 1045, in _bootstrap_inner
    self.run()
  File "/root/anaconda3/lib/python3.11/threading.py", line 982, in run
    self._target(*self._args, **self._kwargs)
  File "/root/anaconda3/lib/python3.11/site-packages/django/utils/autoreload.py", line 64, in wrapper
    fn(*args, **kwargs)
  File "/root/anaconda3/lib/python3.11/site-packages/django/core/management/commands/runserver.py", line 133, in inner_run
    self.check(display_num_errors=True)
  File "/root/anaconda3/lib/python3.11/site-packages/django/core/management/base.py", line 486, in check
    all_issues = checks.run_checks(
                 ^^^^^^^^^^^^^^^^^^
  File "/root/anaconda3/lib/python3.11/site-packages/django/core/checks/registry.py", line 88, in run_checks
    new_errors = check(app_configs=app_configs, databases=databases)
                 ^^^^^^^^^^^^^^^^^^^^^^^^^^^^^^^^^^^^^^^^^^^^^^^^^^^
  File "/root/anaconda3/lib/python3.11/site-packages/django/core/checks/urls.py", line 42, in check_url_namespaces_unique
    all_namespaces = _load_all_namespaces(resolver)
                     ^^^^^^^^^^^^^^^^^^^^^^^^^^^^^^
  File "/root/anaconda3/lib/python3.11/site-packages/django/core/checks/urls.py", line 61, in _load_all_namespaces
    url_patterns = getattr(resolver, "url_patterns", [])
                   ^^^^^^^^^^^^^^^^^^^^^^^^^^^^^^^^^^^^^
  File "/root/anaconda3/lib/python3.11/site-packages/django/utils/functional.py", line 47, in __get__
    res = instance.__dict__[self.name] = self.func(instance)
                                         ^^^^^^^^^^^^^^^^^^^
  File "/root/anaconda3/lib/python3.11/site-packages/django/urls/resolvers.py", line 738, in url_patterns
    patterns = getattr(self.urlconf_module, "urlpatterns", self.urlconf_module)
                       ^^^^^^^^^^^^^^^^^^^
  File "/root/anaconda3/lib/python3.11/site-packages/django/utils/functional.py", line 47, in __get__
    res = instance.__dict__[self.name] = self.func(instance)
                                         ^^^^^^^^^^^^^^^^^^^
  File "/root/anaconda3/lib/python3.11/site-packages/django/urls/resolvers.py", line 731, in urlconf_module
    return import_module(self.urlconf_name)
           ^^^^^^^^^^^^^^^^^^^^^^^^^^^^^^^^
  File "/root/anaconda3/lib/python3.11/importlib/__init__.py", line 126, in import_module
    return _bootstrap._gcd_import(name[level:], package, level)
           ^^^^^^^^^^^^^^^^^^^^^^^^^^^^^^^^^^^^^^^^^^^^^^^^^^^^
  File "<frozen importlib._bootstrap>", line 1204, in _gcd_import
  File "<frozen importlib._bootstrap>", line 1176, in _find_and_load
  File "<frozen importlib._bootstrap>", line 1147, in _find_and_load_unlocked
  File "<frozen importlib._bootstrap>", line 690, in _load_unlocked
  File "<frozen importlib._bootstrap_external>", line 940, in exec_module
  File "<frozen importlib._bootstrap>", line 241, in _call_with_frames_removed
  File "/mnt/share_ubuntu/registr_page/registr_page/urls.py", line 22, in <module>
    path('register/', views.register, name='register'),
                      ^^^^^
NameError: name 'views' is not defined





Page not found (404)
Request Method: 	GET
Request URL: 	http://localhost:8000/

Using the URLconf defined in registr_page.urls, Django tried these URL patterns, in this order:

    admin/
    register/ [name='register']

The empty path didn’t match any of these.

You’re seeing this error because you have DEBUG = True in your Django settings file. Change that to False, and Django will display a standard 404 page.




Page not found (404)
Request Method: 	GET
Request URL: 	http://localhost:8000/

Using the URLconf defined in registr_page.urls, Django tried these URL patterns, in this order:

    admin/
    register/ [name='register']

The empty path didn’t match any of these.

You’re seeing this error because you have DEBUG = True in your Django settings file. Change that to False, and Django will display a standard 404 page.


base) root@askar-VirtualBox:/mnt/share_ubuntu/registr_page# python3.11 manage.py runserver
Watching for file changes with StatReloader
Performing system checks...

Exception in thread django-main-thread:
Traceback (most recent call last):
  File "/root/anaconda3/lib/python3.11/threading.py", line 1045, in _bootstrap_inner
    self.run()
  File "/root/anaconda3/lib/python3.11/threading.py", line 982, in run
    self._target(*self._args, **self._kwargs)
  File "/root/anaconda3/lib/python3.11/site-packages/django/utils/autoreload.py", line 64, in wrapper
    fn(*args, **kwargs)
  File "/root/anaconda3/lib/python3.11/site-packages/django/core/management/commands/runserver.py", line 133, in inner_run
    self.check(display_num_errors=True)
  File "/root/anaconda3/lib/python3.11/site-packages/django/core/management/base.py", line 486, in check
    all_issues = checks.run_checks(
                 ^^^^^^^^^^^^^^^^^^
  File "/root/anaconda3/lib/python3.11/site-packages/django/core/checks/registry.py", line 88, in run_checks
    new_errors = check(app_configs=app_configs, databases=databases)
                 ^^^^^^^^^^^^^^^^^^^^^^^^^^^^^^^^^^^^^^^^^^^^^^^^^^^
  File "/root/anaconda3/lib/python3.11/site-packages/django/core/checks/urls.py", line 42, in check_url_namespaces_unique
    all_namespaces = _load_all_namespaces(resolver)
                     ^^^^^^^^^^^^^^^^^^^^^^^^^^^^^^
  File "/root/anaconda3/lib/python3.11/site-packages/django/core/checks/urls.py", line 61, in _load_all_namespaces
    url_patterns = getattr(resolver, "url_patterns", [])
                   ^^^^^^^^^^^^^^^^^^^^^^^^^^^^^^^^^^^^^
  File "/root/anaconda3/lib/python3.11/site-packages/django/utils/functional.py", line 47, in __get__
    res = instance.__dict__[self.name] = self.func(instance)
                                         ^^^^^^^^^^^^^^^^^^^
  File "/root/anaconda3/lib/python3.11/site-packages/django/urls/resolvers.py", line 738, in url_patterns
    patterns = getattr(self.urlconf_module, "urlpatterns", self.urlconf_module)
                       ^^^^^^^^^^^^^^^^^^^
  File "/root/anaconda3/lib/python3.11/site-packages/django/utils/functional.py", line 47, in __get__
    res = instance.__dict__[self.name] = self.func(instance)
                                         ^^^^^^^^^^^^^^^^^^^
  File "/root/anaconda3/lib/python3.11/site-packages/django/urls/resolvers.py", line 731, in urlconf_module
    return import_module(self.urlconf_name)
           ^^^^^^^^^^^^^^^^^^^^^^^^^^^^^^^^
  File "/root/anaconda3/lib/python3.11/importlib/__init__.py", line 126, in import_module
    return _bootstrap._gcd_import(name[level:], package, level)
           ^^^^^^^^^^^^^^^^^^^^^^^^^^^^^^^^^^^^^^^^^^^^^^^^^^^^
  File "<frozen importlib._bootstrap>", line 1204, in _gcd_import
  File "<frozen importlib._bootstrap>", line 1176, in _find_and_load
  File "<frozen importlib._bootstrap>", line 1147, in _find_and_load_unlocked
  File "<frozen importlib._bootstrap>", line 690, in _load_unlocked
  File "<frozen importlib._bootstrap_external>", line 940, in exec_module
  File "<frozen importlib._bootstrap>", line 241, in _call_with_frames_removed
  File "/mnt/share_ubuntu/registr_page/registr_page/urls.py", line 24, in <module>
    path('register/', include('registration.urls')),  # Убедись, что у тебя есть urls.py в приложении registration
                      ^^^^^^^
NameError: name 'include' is not defined




Page not found (404)
Request Method: 	GET
Request URL: 	http://localhost:8000/

Using the URLconf defined in registr_page.urls, Django tried these URL patterns, in this order:

    admin/
    register/

The empty path didn’t match any of these.

You’re seeing this error because you have DEBUG = True in your Django settings file. Change that to False, and Django will display a standard 404 page.





TemplateDoesNotExist at /

registration/register.html

Request Method: 	GET
Request URL: 	http://localhost:8000/
Django Version: 	5.0.4
Exception Type: 	TemplateDoesNotExist
Exception Value: 	

registration/register.html

Exception Location: 	/root/anaconda3/lib/python3.11/site-packages/django/template/loader.py, line 19, in get_template
Raised during: 	registration.views.register
Python Executable: 	/root/anaconda3/bin/python3.11
Python Version: 	3.11.7
Python Path: 	

['/mnt/share_ubuntu/registr_page',
 '/root/anaconda3/lib/python311.zip',
 '/root/anaconda3/lib/python3.11',
 '/root/anaconda3/lib/python3.11/lib-dynload',
 '/root/anaconda3/lib/python3.11/site-packages']

Server time: 	Sun, 21 Apr 2024 13:59:38 +0000
Template-loader postmortem

Django tried loading these templates, in this order:

Using engine django:

    django.template.loaders.app_directories.Loader: /root/anaconda3/lib/python3.11/site-packages/django/contrib/admin/templates/registration/register.html (Source does not exist)
    django.template.loaders.app_directories.Loader: /root/anaconda3/lib/python3.11/site-packages/django/contrib/auth/templates/registration/register.html (Source does not exist)
    django.template.loaders.app_directories.Loader: /mnt/share_ubuntu/registr_page/registration/templates/registration/register.html (Source does not exist)







(base) root@askar-VirtualBox:/mnt/share_ubuntu/registr_page# python3.11 manage.py runserver
Watching for file changes with StatReloader
Performing system checks...

System check identified no issues (0 silenced).
April 21, 2024 - 13:59:36
Django version 5.0.4, using settings 'registr_page.settings'
Starting development server at http://127.0.0.1:8000/
Quit the server with CONTROL-C.

Internal Server Error: /
Traceback (most recent call last):
  File "/root/anaconda3/lib/python3.11/site-packages/django/core/handlers/exception.py", line 55, in inner
    response = get_response(request)
               ^^^^^^^^^^^^^^^^^^^^^
  File "/root/anaconda3/lib/python3.11/site-packages/django/core/handlers/base.py", line 197, in _get_response
    response = wrapped_callback(request, *callback_args, **callback_kwargs)
               ^^^^^^^^^^^^^^^^^^^^^^^^^^^^^^^^^^^^^^^^^^^^^^^^^^^^^^^^^^^^
  File "/mnt/share_ubuntu/registr_page/registration/views.py", line 12, in register
    return render(request, 'registration/register.html', {'form': form})
           ^^^^^^^^^^^^^^^^^^^^^^^^^^^^^^^^^^^^^^^^^^^^^^^^^^^^^^^^^^^^^
  File "/root/anaconda3/lib/python3.11/site-packages/django/shortcuts.py", line 25, in render
    content = loader.render_to_string(template_name, context, request, using=using)
              ^^^^^^^^^^^^^^^^^^^^^^^^^^^^^^^^^^^^^^^^^^^^^^^^^^^^^^^^^^^^^^^^^^^^^
  File "/root/anaconda3/lib/python3.11/site-packages/django/template/loader.py", line 61, in render_to_string
    template = get_template(template_name, using=using)
               ^^^^^^^^^^^^^^^^^^^^^^^^^^^^^^^^^^^^^^^^
  File "/root/anaconda3/lib/python3.11/site-packages/django/template/loader.py", line 19, in get_template
    raise TemplateDoesNotExist(template_name, chain=chain)
django.template.exceptions.TemplateDoesNotExist: registration/register.html
[21/Apr/2024 13:59:38] "GET / HTTP/1.1" 500 75819
^C(base) root@askar-VirtualBox:/mnt/share_ubuntu/registr_page# python3.11 manage.py runserver
Watching for file changes with StatReloader
Performing system checks...

System check identified no issues (0 silenced).
April 21, 2024 - 14:02:06
Django version 5.0.4, using settings 'registr_page.settings'
Starting development server at http://127.0.0.1:8000/
Quit the server with CONTROL-C.

Internal Server Error: /
Traceback (most recent call last):
  File "/root/anaconda3/lib/python3.11/site-packages/django/core/handlers/exception.py", line 55, in inner
    response = get_response(request)
               ^^^^^^^^^^^^^^^^^^^^^
  File "/root/anaconda3/lib/python3.11/site-packages/django/core/handlers/base.py", line 197, in _get_response
    response = wrapped_callback(request, *callback_args, **callback_kwargs)
               ^^^^^^^^^^^^^^^^^^^^^^^^^^^^^^^^^^^^^^^^^^^^^^^^^^^^^^^^^^^^
  File "/mnt/share_ubuntu/registr_page/registration/views.py", line 12, in register
    return render(request, 'registration/register.html', {'form': form})
           ^^^^^^^^^^^^^^^^^^^^^^^^^^^^^^^^^^^^^^^^^^^^^^^^^^^^^^^^^^^^^
  File "/root/anaconda3/lib/python3.11/site-packages/django/shortcuts.py", line 25, in render
    content = loader.render_to_string(template_name, context, request, using=using)
              ^^^^^^^^^^^^^^^^^^^^^^^^^^^^^^^^^^^^^^^^^^^^^^^^^^^^^^^^^^^^^^^^^^^^^
  File "/root/anaconda3/lib/python3.11/site-packages/django/template/loader.py", line 61, in render_to_string
    template = get_template(template_name, using=using)
               ^^^^^^^^^^^^^^^^^^^^^^^^^^^^^^^^^^^^^^^^
  File "/root/anaconda3/lib/python3.11/site-packages/django/template/loader.py", line 19, in get_template
    raise TemplateDoesNotExist(template_name, chain=chain)
django.template.exceptions.TemplateDoesNotExist: registration/register.html
[21/Apr/2024 14:02:09] "GET / HTTP/1.1" 500 75819





NoReverseMatch at /

Reverse for 'login' not found. 'login' is not a valid view function or pattern name.

Request Method: 	POST
Request URL: 	http://localhost:8000/
Django Version: 	5.0.4
Exception Type: 	NoReverseMatch
Exception Value: 	

Reverse for 'login' not found. 'login' is not a valid view function or pattern name.

Exception Location: 	/root/anaconda3/lib/python3.11/site-packages/django/urls/resolvers.py, line 851, in _reverse_with_prefix
Raised during: 	registration.views.register
Python Executable: 	/root/anaconda3/bin/python3.11
Python Version: 	3.11.7
Python Path: 	

['/mnt/share_ubuntu/registr_page',
 '/root/anaconda3/lib/python311.zip',
 '/root/anaconda3/lib/python3.11',
 '/root/anaconda3/lib/python3.11/lib-dynload',
 '/root/anaconda3/lib/python3.11/site-packages']

Server time: 	Sun, 21 Apr 2024 14:06:10 +0000




(base) root@askar-VirtualBox:/mnt/share_ubuntu/registr_page# python3.11 manage.py runserver
Watching for file changes with StatReloader
Performing system checks...

System check identified no issues (0 silenced).
April 21, 2024 - 14:12:57
Django version 5.0.4, using settings 'registr_page.settings'
Starting development server at http://127.0.0.1:8000/
Quit the server with CONTROL-C.

Internal Server Error: /
Traceback (most recent call last):
  File "/root/anaconda3/lib/python3.11/site-packages/django/core/handlers/exception.py", line 55, in inner
    response = get_response(request)
               ^^^^^^^^^^^^^^^^^^^^^
  File "/root/anaconda3/lib/python3.11/site-packages/django/core/handlers/base.py", line 197, in _get_response
    response = wrapped_callback(request, *callback_args, **callback_kwargs)
               ^^^^^^^^^^^^^^^^^^^^^^^^^^^^^^^^^^^^^^^^^^^^^^^^^^^^^^^^^^^^
  File "/mnt/share_ubuntu/registr_page/registration/views.py", line 10, in register
    user.password = make_password(form.cleaned_data['password'])
                    ^^^^^^^^^^^^^
NameError: name 'make_password' is not defined
[21/Apr/2024 14:13:01] "POST / HTTP/1.1" 500 63296

pbkdf2_sha256$720000$wsZmO4nATz2VmC8KQiWWy2$Rtdvu6rbnPZKKpwmZtH2aOo4d9xhfQkoxFQ0IFZ6Cr0=





Page not found (404)
Request Method: 	GET
Request URL: 	http://localhost:8000/accounts/profile/

Using the URLconf defined in registr_page.urls, Django tried these URL patterns, in this order:

    admin/
    register/
    [name='register']
    login/ [name='login']

The current path, accounts/profile/, didn’t match any of these.

You’re seeing this error because you have DEBUG = True in your Django settings file. Change that to False, and Django will display a standard 404 page.




(base) root@askar-VirtualBox:/mnt/share_ubuntu/registr_page/registr_page# python3.11 ../manage.py runserver
Watching for file changes with StatReloader
Performing system checks...

System check identified no issues (0 silenced).
Exception in thread django-main-thread:
Traceback (most recent call last):
  File "/root/anaconda3/lib/python3.11/site-packages/django/db/backends/base/base.py", line 275, in ensure_connection
    self.connect()
  File "/root/anaconda3/lib/python3.11/site-packages/django/utils/asyncio.py", line 26, in inner
    return func(*args, **kwargs)
           ^^^^^^^^^^^^^^^^^^^^^
  File "/root/anaconda3/lib/python3.11/site-packages/django/db/backends/base/base.py", line 256, in connect
    self.connection = self.get_new_connection(conn_params)
                      ^^^^^^^^^^^^^^^^^^^^^^^^^^^^^^^^^^^^
  File "/root/anaconda3/lib/python3.11/site-packages/mssql/base.py", line 368, in get_new_connection
    conn = Database.connect(connstr, **args)
           ^^^^^^^^^^^^^^^^^^^^^^^^^^^^^^^^^
pyodbc.OperationalError: ('HYT00', '[HYT00] [Microsoft][ODBC Driver 17 for SQL Server]Login timeout expired (0) (SQLDriverConnect)')

The above exception was the direct cause of the following exception:

Traceback (most recent call last):
  File "/root/anaconda3/lib/python3.11/threading.py", line 1045, in _bootstrap_inner
    self.run()
  File "/root/anaconda3/lib/python3.11/threading.py", line 982, in run
    self._target(*self._args, **self._kwargs)
  File "/root/anaconda3/lib/python3.11/site-packages/django/utils/autoreload.py", line 64, in wrapper
    fn(*args, **kwargs)
  File "/root/anaconda3/lib/python3.11/site-packages/django/core/management/commands/runserver.py", line 136, in inner_run
    self.check_migrations()
  File "/root/anaconda3/lib/python3.11/site-packages/django/core/management/base.py", line 581, in check_migrations
    executor = MigrationExecutor(connections[DEFAULT_DB_ALIAS])
               ^^^^^^^^^^^^^^^^^^^^^^^^^^^^^^^^^^^^^^^^^^^^^^^^
  File "/root/anaconda3/lib/python3.11/site-packages/django/db/migrations/executor.py", line 18, in __init__
    self.loader = MigrationLoader(self.connection)
                  ^^^^^^^^^^^^^^^^^^^^^^^^^^^^^^^^
  File "/root/anaconda3/lib/python3.11/site-packages/django/db/migrations/loader.py", line 58, in __init__
    self.build_graph()
  File "/root/anaconda3/lib/python3.11/site-packages/django/db/migrations/loader.py", line 235, in build_graph
    self.applied_migrations = recorder.applied_migrations()
                              ^^^^^^^^^^^^^^^^^^^^^^^^^^^^^
  File "/root/anaconda3/lib/python3.11/site-packages/django/db/migrations/recorder.py", line 89, in applied_migrations
    if self.has_table():
       ^^^^^^^^^^^^^^^^
  File "/root/anaconda3/lib/python3.11/site-packages/django/db/migrations/recorder.py", line 63, in has_table
    with self.connection.cursor() as cursor:
         ^^^^^^^^^^^^^^^^^^^^^^^^
  File "/root/anaconda3/lib/python3.11/site-packages/django/utils/asyncio.py", line 26, in inner
    return func(*args, **kwargs)
           ^^^^^^^^^^^^^^^^^^^^^
  File "/root/anaconda3/lib/python3.11/site-packages/django/db/backends/base/base.py", line 316, in cursor
    return self._cursor()
           ^^^^^^^^^^^^^^
  File "/root/anaconda3/lib/python3.11/site-packages/mssql/base.py", line 261, in _cursor
    conn = super()._cursor()
           ^^^^^^^^^^^^^^^^^
  File "/root/anaconda3/lib/python3.11/site-packages/django/db/backends/base/base.py", line 292, in _cursor
    self.ensure_connection()
  File "/root/anaconda3/lib/python3.11/site-packages/django/utils/asyncio.py", line 26, in inner
    return func(*args, **kwargs)
           ^^^^^^^^^^^^^^^^^^^^^
  File "/root/anaconda3/lib/python3.11/site-packages/django/db/backends/base/base.py", line 274, in ensure_connection
    with self.wrap_database_errors:
  File "/root/anaconda3/lib/python3.11/site-packages/django/db/utils.py", line 91, in __exit__
    raise dj_exc_value.with_traceback(traceback) from exc_value
  File "/root/anaconda3/lib/python3.11/site-packages/django/db/backends/base/base.py", line 275, in ensure_connection
    self.connect()
  File "/root/anaconda3/lib/python3.11/site-packages/django/utils/asyncio.py", line 26, in inner
    return func(*args, **kwargs)
           ^^^^^^^^^^^^^^^^^^^^^
  File "/root/anaconda3/lib/python3.11/site-packages/django/db/backends/base/base.py", line 256, in connect
    self.connection = self.get_new_connection(conn_params)
                      ^^^^^^^^^^^^^^^^^^^^^^^^^^^^^^^^^^^^
  File "/root/anaconda3/lib/python3.11/site-packages/mssql/base.py", line 368, in get_new_connection
    conn = Database.connect(connstr, **args)
           ^^^^^^^^^^^^^^^^^^^^^^^^^^^^^^^^^
django.db.utils.OperationalError: ('HYT00', '[HYT00] [Microsoft][ODBC Driver 17 for SQL Server]Login timeout expired (0) (SQLDriverConnect)')
